2020-06-11 17:42:02,672 ERROR: Exception on /index [GET] [in c:\users\hp\desktop\todomagic\venv\lib\site-packages\flask\app.py:1891]
Traceback (most recent call last):
  File "c:\users\hp\desktop\todomagic\venv\lib\site-packages\sqlalchemy\engine\base.py", line 1283, in _execute_context
    self.dialect.do_execute(
  File "c:\users\hp\desktop\todomagic\venv\lib\site-packages\sqlalchemy\engine\default.py", line 590, in do_execute
    cursor.execute(statement, parameters)
sqlite3.OperationalError: attempt to write a readonly database

The above exception was the direct cause of the following exception:

Traceback (most recent call last):
  File "c:\users\hp\desktop\todomagic\venv\lib\site-packages\flask\app.py", line 2447, in wsgi_app
    response = self.full_dispatch_request()
  File "c:\users\hp\desktop\todomagic\venv\lib\site-packages\flask\app.py", line 1952, in full_dispatch_request
    rv = self.handle_user_exception(e)
  File "c:\users\hp\desktop\todomagic\venv\lib\site-packages\flask\app.py", line 1821, in handle_user_exception
    reraise(exc_type, exc_value, tb)
  File "c:\users\hp\desktop\todomagic\venv\lib\site-packages\flask\_compat.py", line 39, in reraise
    raise value
  File "c:\users\hp\desktop\todomagic\venv\lib\site-packages\flask\app.py", line 1948, in full_dispatch_request
    rv = self.preprocess_request()
  File "c:\users\hp\desktop\todomagic\venv\lib\site-packages\flask\app.py", line 2242, in preprocess_request
    rv = func()
  File "C:\Users\HP\Desktop\todomagic\app\routes.py", line 31, in before_request
    db.session.commit()
  File "c:\users\hp\desktop\todomagic\venv\lib\site-packages\sqlalchemy\orm\scoping.py", line 163, in do
    return getattr(self.registry(), name)(*args, **kwargs)
  File "c:\users\hp\desktop\todomagic\venv\lib\site-packages\sqlalchemy\orm\session.py", line 1042, in commit
    self.transaction.commit()
  File "c:\users\hp\desktop\todomagic\venv\lib\site-packages\sqlalchemy\orm\session.py", line 504, in commit
    self._prepare_impl()
  File "c:\users\hp\desktop\todomagic\venv\lib\site-packages\sqlalchemy\orm\session.py", line 483, in _prepare_impl
    self.session.flush()
  File "c:\users\hp\desktop\todomagic\venv\lib\site-packages\sqlalchemy\orm\session.py", line 2523, in flush
    self._flush(objects)
  File "c:\users\hp\desktop\todomagic\venv\lib\site-packages\sqlalchemy\orm\session.py", line 2664, in _flush
    transaction.rollback(_capture_exception=True)
  File "c:\users\hp\desktop\todomagic\venv\lib\site-packages\sqlalchemy\util\langhelpers.py", line 68, in __exit__
    compat.raise_(
  File "c:\users\hp\desktop\todomagic\venv\lib\site-packages\sqlalchemy\util\compat.py", line 178, in raise_
    raise exception
  File "c:\users\hp\desktop\todomagic\venv\lib\site-packages\sqlalchemy\orm\session.py", line 2624, in _flush
    flush_context.execute()
  File "c:\users\hp\desktop\todomagic\venv\lib\site-packages\sqlalchemy\orm\unitofwork.py", line 422, in execute
    rec.execute(self)
  File "c:\users\hp\desktop\todomagic\venv\lib\site-packages\sqlalchemy\orm\unitofwork.py", line 586, in execute
    persistence.save_obj(
  File "c:\users\hp\desktop\todomagic\venv\lib\site-packages\sqlalchemy\orm\persistence.py", line 230, in save_obj
    _emit_update_statements(
  File "c:\users\hp\desktop\todomagic\venv\lib\site-packages\sqlalchemy\orm\persistence.py", line 994, in _emit_update_statements
    c = cached_connections[connection].execute(
  File "c:\users\hp\desktop\todomagic\venv\lib\site-packages\sqlalchemy\engine\base.py", line 1020, in execute
    return meth(self, multiparams, params)
  File "c:\users\hp\desktop\todomagic\venv\lib\site-packages\sqlalchemy\sql\elements.py", line 298, in _execute_on_connection
    return connection._execute_clauseelement(self, multiparams, params)
  File "c:\users\hp\desktop\todomagic\venv\lib\site-packages\sqlalchemy\engine\base.py", line 1133, in _execute_clauseelement
    ret = self._execute_context(
  File "c:\users\hp\desktop\todomagic\venv\lib\site-packages\sqlalchemy\engine\base.py", line 1323, in _execute_context
    self._handle_dbapi_exception(
  File "c:\users\hp\desktop\todomagic\venv\lib\site-packages\sqlalchemy\engine\base.py", line 1517, in _handle_dbapi_exception
    util.raise_(
  File "c:\users\hp\desktop\todomagic\venv\lib\site-packages\sqlalchemy\util\compat.py", line 178, in raise_
    raise exception
  File "c:\users\hp\desktop\todomagic\venv\lib\site-packages\sqlalchemy\engine\base.py", line 1283, in _execute_context
    self.dialect.do_execute(
  File "c:\users\hp\desktop\todomagic\venv\lib\site-packages\sqlalchemy\engine\default.py", line 590, in do_execute
    cursor.execute(statement, parameters)
sqlalchemy.exc.OperationalError: (sqlite3.OperationalError) attempt to write a readonly database
[SQL: UPDATE user SET last_seen=? WHERE user.id = ?]
[parameters: ('2020-06-11 12:12:02.672473', 2)]
(Background on this error at: http://sqlalche.me/e/e3q8)
2020-06-11 17:44:20,350 INFO: TodoMagic startup [in C:\Users\HP\Desktop\todomagic\app\__init__.py:49]
2020-06-11 17:45:04,019 INFO: TodoMagic startup [in C:\Users\HP\Desktop\todomagic\app\__init__.py:49]
2020-06-11 17:50:39,403 INFO: TodoMagic startup [in C:\Users\HP\Desktop\todomagic\app\__init__.py:49]
